<?xml version="1.0" encoding="utf-8"?>
<!-- This URDF was automatically created by SolidWorks to URDF Exporter! Originally created by Stephen Brawner (brawner@gmail.com) 
     Commit Version: 1.6.0-4-g7f85cfe  Build Version: 1.6.7995.38578
     For more information, please see http://wiki.ros.org/sw_urdf_exporter -->
<robot
  name="robot">
  <link
    name="base_link">
    <inertial>
      <origin
        xyz="6.8677E-06 -0.027077 0.022462"
        rpy="0 0 0" />
      <mass
        value="0.97387" />
      <inertia
        ixx="0.0025835"
        ixy="1.4512E-05"
        ixz="-7.1983E-06"
        iyy="0.0026984"
        iyz="-1.5132E-07"
        izz="0.0048085" />
    </inertial>
    <visual>
      <origin
        xyz="0 0 0"
        rpy="0 0 0" />
      <geometry>
        <mesh
          filename="package://robot/meshes/base_link.STL" />
      </geometry>
      <material
        name="">
        <color
          rgba="0.79216 0.81961 0.93333 1" />
      </material>
    </visual>
    <collision>
      <origin
        xyz="0 0 0"
        rpy="0 0 0" />
      <geometry>
        <mesh
          filename="package://robot/meshes/base_link.STL" />
      </geometry>
    </collision>
  </link>
  <link
    name="fr_Link">
    <inertial>
      <origin
        xyz="-0.017729 -1.3087E-05 4.7967E-05"
        rpy="0 0 0" />
      <mass
        value="0.12331" />
      <inertia
        ixx="3.1197E-05"
        ixy="-9.8423E-14"
        ixz="9.1364E-14"
        iyy="2.3803E-05"
        iyz="2.2611E-12"
        izz="2.3803E-05" />
    </inertial>
    <visual>
      <origin
        xyz="0 0 0"
        rpy="0 0 0" />
      <geometry>
        <mesh
          filename="package://robot/meshes/fr_Link.STL" />
      </geometry>
      <material
        name="">
        <color
          rgba="0.25098 0.25098 0.25098 1" />
      </material>
    </visual>
    <collision>
      <origin
        xyz="0 0 0"
        rpy="0 0 0" />
      <geometry>
        <mesh
          filename="package://robot/meshes/fr_Link.STL" />
      </geometry>
    </collision>
  </link>
  <joint
    name="fr"
    type="continuous">
    <origin
      xyz="-0.14541 -0.09055 -0.019003"
      rpy="0 0 3.1416" />
    <parent
      link="base_link" />
    <child
      link="fr_Link" />
    <axis
      xyz="1 0 0" />
  </joint>
  <link
    name="fl_Link">
    <inertial>
      <origin
        xyz="-0.017729 -4.9653E-05 2.5688E-06"
        rpy="0 0 0" />
      <mass
        value="0.12331" />
      <inertia
        ixx="3.1197E-05"
        ixy="-1.5121E-13"
        ixz="-3.6164E-14"
        iyy="2.3803E-05"
        iyz="-1.4356E-12"
        izz="2.3803E-05" />
    </inertial>
    <visual>
      <origin
        xyz="0 0 0"
        rpy="0 0 0" />
      <geometry>
        <mesh
          filename="package://robot/meshes/fl_Link.STL" />
      </geometry>
      <material
        name="">
        <color
          rgba="0.25098 0.25098 0.25098 1" />
      </material>
    </visual>
    <collision>
      <origin
        xyz="0 0 0"
        rpy="0 0 0" />
      <geometry>
        <mesh
          filename="package://robot/meshes/fl_Link.STL" />
      </geometry>
    </collision>
  </link>
  <joint
    name="fl"
    type="continuous">
    <origin
      xyz="0.14942 -0.090549 -0.019003"
      rpy="0 0 0" />
    <parent
      link="base_link" />
    <child
      link="fl_Link" />
    <axis
      xyz="1 0 0" />
  </joint>
  <link
    name="rr_Link">
    <inertial>
      <origin
        xyz="-0.017729 -4.7697E-06 4.9491E-05"
        rpy="0 0 0" />
      <mass
        value="0.12331" />
      <inertia
        ixx="3.1197E-05"
        ixy="-8.191E-14"
        ixz="1.3905E-13"
        iyy="2.3803E-05"
        iyz="1.9168E-12"
        izz="2.3803E-05" />
    </inertial>
    <visual>
      <origin
        xyz="0 0 0"
        rpy="0 0 0" />
      <geometry>
        <mesh
          filename="package://robot/meshes/rr_Link.STL" />
      </geometry>
      <material
        name="">
        <color
          rgba="0.25098 0.25098 0.25098 1" />
      </material>
    </visual>
    <collision>
      <origin
        xyz="0 0 0"
        rpy="0 0 0" />
      <geometry>
        <mesh
          filename="package://robot/meshes/rr_Link.STL" />
      </geometry>
    </collision>
  </link>
  <joint
    name="rr"
    type="continuous">
    <origin
      xyz="-0.14741 0.04645 -0.019003"
      rpy="0 0 3.1416" />
    <parent
      link="base_link" />
    <child
      link="rr_Link" />
    <axis
      xyz="1 0 0" />
  </joint>
  <link
    name="rl_Link">
    <inertial>
      <origin
        xyz="-0.017729 -1.109E-05 4.8467E-05"
        rpy="0 0 0" />
      <mass
        value="0.12331" />
      <inertia
        ixx="3.1197E-05"
        ixy="-9.711E-14"
        ixz="9.4571E-14"
        iyy="2.3803E-05"
        iyz="2.1971E-12"
        izz="2.3803E-05" />
    </inertial>
    <visual>
      <origin
        xyz="0 0 0"
        rpy="0 0 0" />
      <geometry>
        <mesh
          filename="package://robot/meshes/rl_Link.STL" />
      </geometry>
      <material
        name="">
        <color
          rgba="0.25098 0.25098 0.25098 1" />
      </material>
    </visual>
    <collision>
      <origin
        xyz="0 0 0"
        rpy="0 0 0" />
      <geometry>
        <mesh
          filename="package://robot/meshes/rl_Link.STL" />
      </geometry>
    </collision>
  </link>
  <joint
    name="rl"
    type="continuous">
    <origin
      xyz="0.14742 0.04645 -0.019003"
      rpy="0 0 0" />
    <parent
      link="base_link" />
    <child
      link="rl_Link" />
    <axis
      xyz="1 0 0" />
  </joint>
</robot>